<?xml version="1.0"?>

<robot name="robotiq_85_gripper">
  <!-- control -->
  <link name="base_link">
    <inertial>
      <mass value="0" />
      <inertia ixx = "0" ixy = "0" ixz = "0"
               iyx = "0" iyy = "0" iyz = "0"
               izx = "0" izy = "0" izz = "0" />
    </inertial>
  </link>

  <joint name="center_x" type="prismatic">
    <parent link="base_link"/>
    <child link="y_control"/>
    <axis xyz="1 0 0"/>
    <limit effort="1000.0" lower="-0.5" upper="0.5" velocity="0.2"/>
  </joint>

  <link name="y_control">
    <inertial>
      <mass value="0.1" />
      <inertia ixx = "0" ixy = "0" ixz = "0"
               iyx = "0" iyy = "0" iyz = "0"
               izx = "0" izy = "0" izz = "0" />
    </inertial>
  </link>

  <joint name="center_y" type="prismatic">
    <parent link="y_control"/>
    <child link="z_control"/>
    <axis xyz="0 1 0"/>
    <limit effort="1000.0" lower="-0.5" upper="0.5" velocity="0.2"/>
  </joint>

  <link name="z_control">
    <inertial>
      <mass value="0.1" />
      <inertia ixx = "0" ixy = "0" ixz = "0"
               iyx = "0" iyy = "0" iyz = "0"
               izx = "0" izy = "0" izz = "0" />
    </inertial>
  </link>

  <joint name="center_z" type="prismatic">
    <parent link="z_control"/>
    <child link="yaw_control"/>
    <axis xyz="0 0 1"/>
    <limit effort="1000.0" lower="-0.25" upper="1" velocity="0.2"/>
  </joint>

  <link name="yaw_control">
    <inertial>
      <mass value="0.1" />
      <inertia ixx = "0" ixy = "0" ixz = "0"
               iyx = "0" iyy = "0" iyz = "0"
               izx = "0" izy = "0" izz = "0" />
    </inertial>
  </link>

  <joint name="gripper_yaw" type="revolute">
    <parent link="yaw_control"/>
    <child link="pitch_control"/>
    <axis xyz="0 0 1"/>
    <limit lower="-31.4" upper="31.4" velocity="3.14" effort="10000"/>

  </joint>

  <link name="pitch_control">
    <inertial>
      <mass value="0.1" />
      <inertia ixx = "0" ixy = "0" ixz = "0"
               iyx = "0" iyy = "0" iyz = "0"
               izx = "0" izy = "0" izz = "0" />
    </inertial>
  </link>

  <joint name="gripper_pitch" type="revolute">
    <parent link="pitch_control"/>
    <child link="roll_control"/>
    <axis xyz="0 1 0"/>
    <limit lower="-31.4" upper="31.4" velocity="3.14" effort="10000"/>

  </joint>

  <link name="roll_control">
    <inertial>
      <mass value="0.1" />
      <inertia ixx = "0" ixy = "0" ixz = "0"
               iyx = "0" iyy = "0" iyz = "0"
               izx = "0" izy = "0" izz = "0" />
    </inertial>
  </link>

  <joint name="gripper_roll" type="revolute">
    <parent link="roll_control"/>
    <child link="dummy_center_indicator_link"/>
    <axis xyz="1 0 0"/>
    <limit lower="-31.4" upper="31.4" velocity="3.14" effort="100000"/>
  </joint>

  <link name="dummy_center_indicator_link">
    <visual>
      <geometry>
        <box size="0.001 0.001 0.001"/>
      </geometry>
    </visual>
    <inertial>
      <mass value="0" />
      <inertia ixx = "0" ixy = "0" ixz = "0"
               iyx = "0" iyy = "0" iyz = "0"
               izx = "0" izy = "0" izz = "0" />
    </inertial>
  </link>

  <joint name="dummy_center_fixed_joint" type="fixed">
    <parent link="dummy_center_indicator_link"/>
    <child link="robotiq_85_base_link"/>
    <origin xyz="0 0 0.05" />
  </joint>


  <link name="robotiq_85_base_link">
      <contact>
          <friction_anchor/>
          <stiffness value="30000.0"/>
          <damping value="0"/>
          <rolling_friction value="0.03"/>
          <spinning_friction value="0.03"/>
          <lateral_friction value="1"/>
      </contact>
      <visual>
        <geometry>
          <mesh filename="cube.obj" scale=".005 .005 .1"/>
        </geometry>
      </visual>
      <collision>
        <geometry>
          <mesh filename="cube.obj" scale=".005 .005 .1"/>
        </geometry>
      </collision>
      <inertial>
        <mass value="1" />
        <origin xyz="0.0 0.0 0.0" />
        <inertia ixx="1" ixy="0" ixz="0" iyy="1" iyz="0" izz="1"/>
      </inertial>
  </link>
  
  <link name="robotiqf1">
      <contact>
          <friction_anchor/>
          <stiffness value="30000.0"/>
          <damping value="0"/>
          <rolling_friction value="0.03"/>
          <spinning_friction value="0.03"/>
          <lateral_friction value="1"/>
      </contact>
      <visual>
        <geometry>
          <mesh filename="cube.obj" scale=".005 .005 .1"/>
        </geometry>
      </visual>
      <collision>
        <geometry>
          <mesh filename="cube.obj" scale=".005 .005 .1"/>
        </geometry>
      </collision>
      <inertial>
        <mass value="1" />
        <origin xyz="0.0 0.0 0.0" />
        <inertia ixx="1" ixy="0" ixz="0" iyy="1" iyz="0" izz="1"/>
      </inertial>
  </link>
  
  <joint name="gripperl" type="prismatic">
    <parent link="robotiq_85_base_link"/>
    <child link="robotiqf1"/>
    <origin xyz="0 -0.03 0.03 " />
    <axis xyz="0 1 0"/>
    <limit effort="100" lower="-0.03" upper="0.02" velocity="1"/>
  </joint>

</robot>
